<mujoco model="H2">
  <compiler angle="radian" meshdir="meshes/"/>

  <default>
     <joint damping="0.05" armature="0.01" frictionloss="0.2"/>
  </default>
  
  <option timestep="0.001"/>
  <asset>
    <mesh name="pelvis" content_type="model/stl" file="pelvis.stl"/>
    <mesh name="left_hip_pitch_link" content_type="model/stl" file="left_hip_pitch_link.stl"/>
    <mesh name="left_hip_roll_link" content_type="model/stl" file="left_hip_roll_link.stl"/>
    <mesh name="left_hip_yaw_link" content_type="model/stl" file="left_hip_yaw_link.stl"/>
    <mesh name="left_knee_link" content_type="model/stl" file="left_knee_link.stl"/>
    <mesh name="left_ankle_roll_link" content_type="model/stl" file="left_ankle_roll_link.stl"/>
    <mesh name="left_ankle_pitch_link" content_type="model/stl" file="left_ankle_pitch_link.stl"/>
    <mesh name="right_hip_pitch_link" content_type="model/stl" file="right_hip_pitch_link.stl"/>
    <mesh name="right_hip_roll_link" content_type="model/stl" file="right_hip_roll_link.stl"/>
    <mesh name="right_hip_yaw_link" content_type="model/stl" file="right_hip_yaw_link.stl"/>
    <mesh name="right_knee_link" content_type="model/stl" file="right_knee_link.stl"/>
    <mesh name="right_ankle_roll_link" content_type="model/stl" file="right_ankle_roll_link.stl"/>
    <mesh name="right_ankle_pitch_link" content_type="model/stl" file="right_ankle_pitch_link.stl"/>
    <mesh name="waist_yaw_link" content_type="model/stl" file="waist_yaw_link.stl"/>
    <mesh name="waist_roll_link" content_type="model/stl" file="waist_roll_link.stl"/>
    <mesh name="torso_link" content_type="model/stl" file="torso_link.stl"/>
    <mesh name="head_pitch_link" content_type="model/stl" file="head_pitch_link.stl"/>
    <mesh name="head_yaw_link" content_type="model/stl" file="head_yaw_link.stl"/>
    <mesh name="left_shoulder_pitch_link" content_type="model/stl" file="left_shoulder_pitch_link.stl"/>
    <mesh name="left_shoulder_roll_link" content_type="model/stl" file="left_shoulder_roll_link.stl"/>
    <mesh name="left_shoulder_yaw_link" content_type="model/stl" file="left_shoulder_yaw_link.stl"/>
    <mesh name="left_elbow_link" content_type="model/stl" file="left_elbow_link.stl"/>
    <mesh name="left_wrist_roll_link" content_type="model/stl" file="left_wrist_roll_link.stl"/>
    <mesh name="left_wrist_pitch_link" content_type="model/stl" file="left_wrist_pitch_link.stl"/>
    <mesh name="left_wrist_yaw_link" content_type="model/stl" file="left_wrist_yaw_link.stl"/>
    <mesh name="right_shoulder_pitch_link" content_type="model/stl" file="right_shoulder_pitch_link.stl"/>
    <mesh name="right_shoulder_roll_link" content_type="model/stl" file="right_shoulder_roll_link.stl"/>
    <mesh name="right_shoulder_yaw_link" content_type="model/stl" file="right_shoulder_yaw_link.stl"/>
    <mesh name="right_elbow_link" content_type="model/stl" file="right_elbow_link.stl"/>
    <mesh name="right_wrist_roll_link" content_type="model/stl" file="right_wrist_roll_link.stl"/>
    <mesh name="right_wrist_pitch_link" content_type="model/stl" file="right_wrist_pitch_link.stl"/>
    <mesh name="right_wrist_yaw_link" content_type="model/stl" file="right_wrist_yaw_link.stl"/>
  </asset>

  <worldbody>
    <body name="pelvis" pos="0 0 1.2">
      <site name="imu" size="0.01" pos="0.0 0.0 0.0"/>
      <joint name="floating_base_joint" type="free" limited="false" actuatorfrclimited="false"/>
    <geom type="mesh" contype="0" conaffinity="0" group="1" density="0" rgba="0.7 0.7 0.7 1" mesh="pelvis"/>
    <geom type="mesh" rgba="0.7 0.7 0.7 1" mesh="pelvis"/>
    <body name="left_hip_pitch_link" pos="0 0.08038 -0.046407" quat="0.965926 -0.25882 0 0">
      <inertial pos="0.00294368 0.061102 -0.017351" quat="0.89044 0.453883 -0.0133707 -0.0304704" mass="2.8737" diaginertia="0.00537408 0.00421163 0.0036878"/>
      <joint name="left_hip_pitch_joint" pos="0 0 0" axis="0 1 0" range="-2.4526 2.77542" actuatorfrcrange="-360 360"/>
      <geom type="mesh" contype="0" conaffinity="0" group="1" density="0" rgba="0.4 0.4 0.4 1" mesh="left_hip_pitch_link"/>
      <body name="left_hip_roll_link" pos="0.041774 0.0635 -0.019" quat="0.965926 0.25882 0 0">
        <inertial pos="-0.0175789 -0.00607425 -0.041315" quat="-0.165515 0.598251 -0.0524355 0.782273" mass="0.785079" diaginertia="0.0023778 0.00200443 0.0015153"/>
        <joint name="left_hip_roll_joint" pos="0 0 0" axis="1 0 0" range="-0.467441 2.16886" actuatorfrcrange="-360 360"/>
        <geom type="mesh" contype="0" conaffinity="0" group="1" density="0" rgba="0.7 0.7 0.7 1" mesh="left_hip_roll_link"/>
        <geom size="0.05" pos="-0.02 0 0" rgba="0.7 0.7 0.7 1"/>
        <body name="left_hip_yaw_link" pos="-0.028187 -0.0095 -0.0737">
          <inertial pos="0.00069408 -0.0108659 -0.113015" quat="0.621956 -0.0405938 0.0198649 0.781747" mass="7.0875" diaginertia="0.0514013 0.0505964 0.0130063"/>
          <joint name="left_hip_yaw_joint" pos="0 0 0" axis="0 0 1" range="-2.827 2.827" actuatorfrcrange="-360 360"/>
          <geom type="mesh" contype="0" conaffinity="0" group="1" density="0" rgba="0.7 0.7 0.7 1" mesh="left_hip_yaw_link"/>
          <geom type="mesh" rgba="0.7 0.7 0.7 1" mesh="left_hip_yaw_link"/>
          <body name="left_knee_link" pos="-0.010308 0.022549 -0.31959">
            <inertial pos="0.00461331 -0.022549 -0.167155" quat="0.689662 0.00325283 0.00290593 0.724118" mass="4.3534" diaginertia="0.0512388 0.0510884 0.00333998"/>
            <joint name="left_knee_joint" pos="0 0 0" axis="0 1 0" range="-0.08725 2.53025" actuatorfrcrange="-360 360"/>
            <geom type="mesh" contype="0" conaffinity="0" group="1" density="0" rgba="0.7 0.7 0.7 1" mesh="left_knee_link"/>
            <geom size="0.025 0.175" pos="0.01 -0.022549 -0.25" type="cylinder" rgba="0.7 0.7 0.7 1"/>
            <body name="left_ankle_roll_link" pos="0.032719 -0.023002 -0.49662">
              <inertial pos="-0.0174063 6.424e-05 -0.0002146" quat="0.499157 0.502573 -0.497809 0.500449" mass="0.123182" diaginertia="4.00501e-05 3.43207e-05 1.44993e-05"/>
              <joint name="left_ankle_roll_joint" pos="0 0 0" axis="1 0 0" range="-0.349066 0.296706" actuatorfrcrange="-19 19"/>
              <geom type="mesh" contype="0" conaffinity="0" group="1" density="0" rgba="0.7 0.7 0.7 1" mesh="left_ankle_roll_link"/>
              <body name="left_ankle_pitch_link" pos="-0.014516 -0.0373 0">
                <inertial pos="0.032059 0.0370053 -0.0288282" quat="6.19452e-05 0.72345 -3.0004e-05 0.690377" mass="0.894967" diaginertia="0.00438317 0.00410964 0.000599978"/>
                <joint name="left_ankle_pitch_joint" pos="0 0 0" axis="0 1 0" range="-1.13446 0.610865" actuatorfrcrange="-66.88 66.88"/>
                <geom type="mesh" contype="0" conaffinity="0" group="1" density="0" rgba="0.4 0.4 0.4 1" mesh="left_ankle_pitch_link"/>
                <geom size="0.008" pos="-0.075 0.066 -0.05" rgba="0.4 0.4 0.4 1"/>
                <geom size="0.008" pos="-0.075 0.007 -0.05" rgba="0.4 0.4 0.4 1"/>
                <geom size="0.008" pos="0.1 0.08 -0.048" rgba="0.4 0.4 0.4 1"/>
                <geom size="0.008" pos="0.1 -0.007 -0.048" rgba="0.4 0.4 0.4 1"/>
                <geom size="0.008" pos="0.15 0.066 -0.05" rgba="0.4 0.4 0.4 1"/>
                <geom size="0.008" pos="0.15 0.007 -0.05" rgba="0.4 0.4 0.4 1"/>
                <geom size="0.115 0.04 0.004" pos="0.035 0.0365 -0.04" type="box" rgba="0.4 0.4 0.4 1"/>
                <site name="left_foot" pos="0.035 0.0365 -0.04" size="0.01"/>
              </body>
            </body>
          </body>
        </body>
      </body>
    </body>
    <body name="right_hip_pitch_link" pos="0 -0.08038 -0.046407" quat="0.965926 0.25882 0 0">
      <inertial pos="0.00294368 -0.061102 -0.017351" quat="0.453883 0.89044 0.0304704 0.0133707" mass="2.8737" diaginertia="0.00537408 0.00421163 0.0036878"/>
      <joint name="right_hip_pitch_joint" pos="0 0 0" axis="0 1 0" range="-2.4526 2.77542" actuatorfrcrange="-360 360"/>
      <geom type="mesh" contype="0" conaffinity="0" group="1" density="0" rgba="0.4 0.4 0.4 1" mesh="right_hip_pitch_link"/>
      <body name="right_hip_roll_link" pos="0.041774 -0.0635 -0.019" quat="0.965926 -0.25882 0 0">
        <inertial pos="-0.0175789 0.00607425 -0.041315" quat="0.165515 0.598251 0.0524355 0.782273" mass="0.75122" diaginertia="0.0023778 0.00200443 0.0015153"/>
        <joint name="right_hip_roll_joint" pos="0 0 0" axis="1 0 0" range="-2.16886 0.467441" actuatorfrcrange="-360 360"/>
        <geom type="mesh" contype="0" conaffinity="0" group="1" density="0" rgba="0.7 0.7 0.7 1" mesh="right_hip_roll_link"/>
        <geom size="0.05" pos="-0.038 0 0" rgba="0.7 0.7 0.7 1"/>
        <body name="right_hip_yaw_link" pos="-0.028187 0.0095 -0.0737">
          <inertial pos="0.00069408 0.0108659 -0.113015" quat="0.781747 0.0198649 -0.0405938 0.621956" mass="7.0875" diaginertia="0.0514013 0.0505964 0.0130063"/>
          <joint name="right_hip_yaw_joint" pos="0 0 0" axis="0 0 1" range="-2.827 2.827" actuatorfrcrange="-360 360"/>
          <geom type="mesh" contype="0" conaffinity="0" group="1" density="0" rgba="0.7 0.7 0.7 1" mesh="right_hip_yaw_link"/>
          <geom type="mesh" rgba="0.7 0.7 0.7 1" mesh="right_hip_yaw_link"/>
          <body name="right_knee_link" pos="-0.010308 -0.022549 -0.31959">
            <inertial pos="0.00461331 0.022549 -0.167155" quat="0.724118 0.00290593 0.00325283 0.689662" mass="4.3534" diaginertia="0.0512388 0.0510884 0.00333998"/>
            <joint name="right_knee_joint" pos="0 0 0" axis="0 1 0" range="-0.08725 2.53025" actuatorfrcrange="-360 360"/>
            <geom type="mesh" contype="0" conaffinity="0" group="1" density="0" rgba="0.7 0.7 0.7 1" mesh="right_knee_link"/>
            <geom size="0.025 0.175" pos="0.01 0.022549 -0.25" type="cylinder" rgba="0.7 0.7 0.7 1"/>
            <body name="right_ankle_roll_link" pos="0.032719 0.023002 -0.49662">
              <inertial pos="-0.0174063 -6.424e-05 -0.0002146" quat="0.502573 0.499157 -0.500449 0.497809" mass="0.123182" diaginertia="4.00501e-05 3.43207e-05 1.44993e-05"/>
              <joint name="right_ankle_roll_joint" pos="0 0 0" axis="1 0 0" range="-0.296706 0.349066" actuatorfrcrange="-19 19"/>
              <geom type="mesh" contype="0" conaffinity="0" group="1" density="0" rgba="0.7 0.7 0.7 1" mesh="right_ankle_roll_link"/>
              <body name="right_ankle_pitch_link" pos="-0.014516 0.0373 0">
                <inertial pos="0.032059 -0.0370053 -0.0288282" quat="-6.19452e-05 0.72345 3.0004e-05 0.690377" mass="0.894967" diaginertia="0.00438317 0.00410964 0.000599978"/>
                <joint name="right_ankle_pitch_joint" pos="0 0 0" axis="0 1 0" range="-1.13446 0.610865" actuatorfrcrange="-66.88 66.88"/>
                <geom type="mesh" contype="0" conaffinity="0" group="1" density="0" rgba="0.4 0.4 0.4 1" mesh="right_ankle_pitch_link"/>
                <geom size="0.008" pos="-0.075 -0.066 -0.05" rgba="0.4 0.4 0.4 1"/>
                <geom size="0.008" pos="-0.075 -0.007 -0.05" rgba="0.4 0.4 0.4 1"/>
                <geom size="0.008" pos="0.1 -0.08 -0.048" rgba="0.4 0.4 0.4 1"/>
                <geom size="0.008" pos="0.1 0.007 -0.048" rgba="0.4 0.4 0.4 1"/>
                <geom size="0.008" pos="0.15 -0.066 -0.05" rgba="0.4 0.4 0.4 1"/>
                <geom size="0.008" pos="0.15 -0.007 -0.05" rgba="0.4 0.4 0.4 1"/>
                <geom size="0.115 0.04 0.004" pos="0.035 -0.0365 -0.04" type="box" rgba="0.4 0.4 0.4 1"/>
                <site name="right_foot" pos="0.035 -0.0365 -0.04" size="0.01"/>
              </body>
            </body>
          </body>
        </body>
      </body>
    </body>
    <body name="waist_yaw_link" pos="0 0 0.090537">
      <inertial pos="0.00648295 1.018e-05 0.0176063" quat="0.000115436 0.720073 0.000256241 0.693898" mass="0.312936" diaginertia="0.00033891 0.00028436 0.00012018"/>
      <joint name="waist_yaw_joint" pos="0 0 0" axis="0 0 1" range="-1.7453 1.7453" actuatorfrcrange="-120 120"/>
      <geom type="mesh" contype="0" conaffinity="0" group="1" density="0" rgba="0.7 0.7 0.7 1" mesh="waist_yaw_link"/>
      <body name="waist_roll_link" pos="0 0 0.0325">
        <inertial pos="0 0.00061119 0" quat="0.5 0.5 -0.5 0.5" mass="0.138419" diaginertia="2.304e-05 1.668e-05 1.509e-05"/>
        <joint name="waist_roll_joint" pos="0 0 0" axis="1 0 0" range="-0.5236 0.5236" actuatorfrcrange="-180 180"/>
        <geom type="mesh" contype="0" conaffinity="0" group="1" density="0" rgba="0.7 0.7 0.7 1" mesh="waist_roll_link"/>
        <body name="torso_link">
          <site name="secondary_imu" size="0.01" pos="0.0 0.0 0.0"/>
          <inertial pos="0.00740421 0.00628045 0.215575" quat="0.99932 -0.0321662 -0.00775231 0.0162839" mass="18.532" diaginertia="0.287321 0.26278 0.0934525"/>
          <joint name="waist_pitch_joint" pos="0 0 0" axis="0 1 0" range="-0.43633 0.5236" actuatorfrcrange="-180 180"/>
          <geom type="mesh" contype="0" conaffinity="0" group="1" density="0" rgba="0.7 0.7 0.7 1" mesh="torso_link"/>
          <geom type="mesh" rgba="0.7 0.7 0.7 1" mesh="torso_link"/>
          <body name="head_pitch_link" pos="-0.0001147 -0.0189 0.4218">
            <inertial pos="0.000126 0.018817 0.052939" quat="0.999996 -0.000955249 -0.00262397 -0.000580497" mass="1.82" diaginertia="0.00538697 0.00532442 0.00140982"/>
            <joint name="head_pitch_joint" pos="0 0 0" axis="0 1 0" range="-0.5236 0.83775" actuatorfrcrange="-50 50"/>
            <geom type="mesh" contype="0" conaffinity="0" group="1" density="0" rgba="0.7 0.7 0.7 1" mesh="head_pitch_link"/>
            <body name="head_yaw_link" pos="0 0.0189 0.1335">
              <inertial pos="0.023654 -0.000734 0.042315" quat="0.667311 -0.227767 -0.231751 0.670156" mass="1.3" diaginertia="0.00535274 0.00472336 0.00378091"/>
              <joint name="head_yaw_joint" pos="0 0 0" axis="0 0 1" range="-1.7453 1.7453" actuatorfrcrange="-50 50"/>
              <geom type="mesh" contype="0" conaffinity="0" group="1" density="0" rgba="0.7 0.7 0.7 1" mesh="head_yaw_link"/>
              <geom type="mesh" rgba="0.7 0.7 0.7 1" mesh="head_yaw_link"/>
            </body>
          </body>
          <body name="left_shoulder_pitch_link" pos="0.0030848 0.11 0.36008" quat="0.990959 0.134164 0 0">
            <inertial pos="-0.0027817 0.050393 -0.023914" quat="0.959427 0.279803 0.00644957 0.0341716" mass="1.1927" diaginertia="0.00174925 0.00162902 0.000852428"/>
            <joint name="left_shoulder_pitch_joint" pos="0 0 0" axis="0 1 0" range="-2.618 1.833" actuatorfrcrange="-130 130"/>
            <geom type="mesh" contype="0" conaffinity="0" group="1" density="0" rgba="0.7 0.7 0.7 1" mesh="left_shoulder_pitch_link"/>
            <geom type="mesh" rgba="0.7 0.7 0.7 1" mesh="left_shoulder_pitch_link"/>
            <body name="left_shoulder_roll_link" pos="-0.0032074 0.059938 -0.039865" quat="0.990959 -0.134164 0 0">
              <inertial pos="-0.00126759 0.00399799 -0.0665267" quat="0.719226 0.0130341 -0.00543937 0.694633" mass="1.10983" diaginertia="0.00193836 0.00176489 0.00106378"/>
              <joint name="left_shoulder_roll_joint" pos="0 0 0" axis="1 0 0" range="-0.517 2.494" actuatorfrcrange="-60 60"/>
              <geom type="mesh" contype="0" conaffinity="0" group="1" density="0" rgba="0.7 0.7 0.7 1" mesh="left_shoulder_roll_link"/>
              <geom type="mesh" rgba="0.7 0.7 0.7 1" mesh="left_shoulder_roll_link"/>
              <body name="left_shoulder_yaw_link" pos="-0.0025601 0.0036752 -0.10421">
                <inertial pos="0.00265957 0.0123454 -0.059622" quat="0.655577 0.0514587 -0.154929 0.737271" mass="0.352739" diaginertia="0.000897689 0.000854204 0.000287447"/>
                <joint name="left_shoulder_yaw_joint" pos="0 0 0" axis="0 0 1" range="-2.618 2.618" actuatorfrcrange="-60 60"/>
                <geom type="mesh" contype="0" conaffinity="0" group="1" density="0" rgba="0.7 0.7 0.7 1" mesh="left_shoulder_yaw_link"/>
                <geom type="mesh" rgba="0.7 0.7 0.7 1" mesh="left_shoulder_yaw_link"/>
                <body name="left_elbow_link" pos="0.016655 0.02211 -0.12792">
                  <inertial pos="0.0506767 -0.0216173 -0.00672238" quat="0.162352 0.731329 0.192833 0.633732" mass="1.70612" diaginertia="0.00522743 0.00521428 0.00111897"/>
                  <joint name="left_elbow_joint" pos="0 0 0" axis="0 1 0" range="-0.986 3.071" actuatorfrcrange="-60 60"/>
                  <geom type="mesh" contype="0" conaffinity="0" group="1" density="0" rgba="0.7 0.7 0.7 1" mesh="left_elbow_link"/>
                  <geom type="mesh" rgba="0.7 0.7 0.7 1" mesh="left_elbow_link"/>
                  <body name="left_wrist_roll_link" pos="0.13119 -0.021497 -0.013769">
                    <inertial pos="0.035915 -0.00154506 0.00012879" quat="0.349429 0.616315 -0.3656 0.603649" mass="0.77426" diaginertia="0.000715547 0.000661189 0.000632495"/>
                    <joint name="left_wrist_roll_joint" pos="0 0 0" axis="1 0 0" range="-2.618 2.618" actuatorfrcrange="-60 60"/>
                    <geom type="mesh" contype="0" conaffinity="0" group="1" density="0" rgba="0.7 0.7 0.7 1" mesh="left_wrist_roll_link"/>
                    <body name="left_wrist_pitch_link" pos="0.037994 0.031144 0.00045104">
                      <inertial pos="0.0651093 -0.0317607 0.00235463" quat="0.491682 0.228754 0.718653 0.435268" mass="0.615258" diaginertia="0.000423535 0.000417983 0.000396162"/>
                      <joint name="left_wrist_pitch_joint" pos="0 0 0" axis="0 1 0" range="-0.576 0.576" actuatorfrcrange="-10 10"/>
                      <geom type="mesh" contype="0" conaffinity="0" group="1" density="0" rgba="0.7 0.7 0.7 1" mesh="left_wrist_pitch_link"/>
                      <body name="left_wrist_yaw_link" pos="0.069283 -0.031045 -0.0006247">
                        <inertial pos="0.0800267 -0.00476807 0.00340465" quat="0.488112 0.56744 0.412641 0.51912" mass="0.616082" diaginertia="0.00189912 0.00166583 0.000524241"/>
                        <joint name="left_wrist_yaw_joint" pos="0 0 0" axis="0 0 1" range="-1.22 1.22" actuatorfrcrange="-10 10"/>
                        <geom type="mesh" contype="0" conaffinity="0" group="1" density="0" rgba="0.4 0.4 0.4 1" mesh="left_wrist_yaw_link"/>
                        <geom type="mesh" rgba="0.4 0.4 0.4 1" mesh="left_wrist_yaw_link"/>
                      </body>
                    </body>
                  </body>
                </body>
              </body>
            </body>
          </body>
          <body name="right_shoulder_pitch_link" pos="0.0030848 -0.11 0.36008" quat="0.990959 -0.134164 0 0">
            <inertial pos="-0.0027814 -0.050393 -0.023914" quat="0.959425 -0.279804 0.00643587 -0.0342398" mass="1.1927" diaginertia="0.00174925 0.00162902 0.000852428"/>
            <joint name="right_shoulder_pitch_joint" pos="0 0 0" axis="0 1 0" range="-2.618 1.833" actuatorfrcrange="-130 130"/>
            <geom type="mesh" contype="0" conaffinity="0" group="1" density="0" rgba="0.7 0.7 0.7 1" mesh="right_shoulder_pitch_link"/>
            <geom type="mesh" rgba="0.7 0.7 0.7 1" mesh="right_shoulder_pitch_link"/>
            <body name="right_shoulder_roll_link" pos="-0.0032074 -0.059938 -0.039865" quat="0.990959 0.134164 0 0">
              <inertial pos="-0.00126782 -0.0039981 -0.0665261" quat="0.694607 -0.0054503 0.0130148 0.719251" mass="1.10982" diaginertia="0.00193838 0.00176496 0.00106379"/>
              <joint name="right_shoulder_roll_joint" pos="0 0 0" axis="1 0 0" range="-2.494 0.517" actuatorfrcrange="-60 60"/>
              <geom type="mesh" contype="0" conaffinity="0" group="1" density="0" rgba="0.7 0.7 0.7 1" mesh="right_shoulder_roll_link"/>
              <geom type="mesh" rgba="0.7 0.7 0.7 1" mesh="right_shoulder_roll_link"/>
              <body name="right_shoulder_yaw_link" pos="-0.0025601 -0.0036752 -0.10421">
                <inertial pos="0.00266059 -0.0123451 -0.0596234" quat="0.737262 -0.154921 0.0514524 0.65559" mass="0.352742" diaginertia="0.000897692 0.000854184 0.000287444"/>
                <joint name="right_shoulder_yaw_joint" pos="0 0 0" axis="0 0 1" range="-2.618 2.618" actuatorfrcrange="-60 60"/>
                <geom type="mesh" contype="0" conaffinity="0" group="1" density="0" rgba="0.7 0.7 0.7 1" mesh="right_shoulder_yaw_link"/>
                <geom type="mesh" rgba="0.7 0.7 0.7 1" mesh="right_shoulder_yaw_link"/>
                <body name="right_elbow_link" pos="0.016655 -0.02211 -0.12792">
                  <inertial pos="0.0506784 0.0216171 -0.00672338" quat="-0.1624 0.731318 -0.192894 0.633713" mass="1.70617" diaginertia="0.00522767 0.0052145 0.00111905"/>
                  <joint name="right_elbow_joint" pos="0 0 0" axis="0 1 0" range="-0.986 3.071" actuatorfrcrange="-60 60"/>
                  <geom type="mesh" contype="0" conaffinity="0" group="1" density="0" rgba="0.7 0.7 0.7 1" mesh="right_elbow_link"/>
                  <geom type="mesh" rgba="0.7 0.7 0.7 1" mesh="right_elbow_link"/>
                  <body name="right_wrist_roll_link" pos="0.13119 0.021497 -0.013769">
                    <inertial pos="0.0359137 0.00155865 0.00014187" quat="0.61587 0.348982 -0.602387 0.368844" mass="0.774265" diaginertia="0.00071595 0.000661595 0.000632525"/>
                    <joint name="right_wrist_roll_joint" pos="0 0 0" axis="1 0 0" range="-2.618 2.618" actuatorfrcrange="-60 60"/>
                    <geom type="mesh" contype="0" conaffinity="0" group="1" density="0" rgba="0.7 0.7 0.7 1" mesh="right_wrist_roll_link"/>
                    <body name="right_wrist_pitch_link" pos="0.037994 -0.031144 0.00045104">
                      <inertial pos="0.0651131 0.0317523 0.00231986" quat="0.440426 0.716762 0.242507 0.483185" mass="0.615837" diaginertia="0.000424256 0.000418373 0.000396861"/>
                      <joint name="right_wrist_pitch_joint" pos="0 0 0" axis="0 1 0" range="-0.576 0.576" actuatorfrcrange="-10 10"/>
                      <geom type="mesh" contype="0" conaffinity="0" group="1" density="0" rgba="0.7 0.7 0.7 1" mesh="right_wrist_pitch_link"/>
                      <body name="right_wrist_yaw_link" pos="0.069283 0.031045 -0.0006247">
                        <inertial pos="0.0800267 0.00476817 0.00340501" quat="0.519117 0.41264 0.567453 0.488102" mass="0.616082" diaginertia="0.00189915 0.00166585 0.00052423"/>
                        <joint name="right_wrist_yaw_joint" pos="0 0 0" axis="0 0 1" range="-1.22 1.22" actuatorfrcrange="-10 10"/>
                        <geom type="mesh" contype="0" conaffinity="0" group="1" density="0" rgba="0.4 0.4 0.4 1" mesh="right_wrist_yaw_link"/>
                        <geom type="mesh" rgba="0.4 0.4 0.4 1" mesh="right_wrist_yaw_link"/>
                      </body>
                    </body>
                  </body>
                </body>
              </body>
            </body>
          </body>
        </body>
      </body>
    </body>
    </body>
  </worldbody>

  <actuator>
    <motor name="left_hip_pitch" joint="left_hip_pitch_joint" ctrlrange="-360 360" />
    <motor name="left_hip_roll" joint="left_hip_roll_joint" ctrlrange="-360 360" />
    <motor name="left_hip_yaw" joint="left_hip_yaw_joint" ctrlrange="-360 360" />
    <motor name="left_knee" joint="left_knee_joint" ctrlrange="-360 360" />
    <motor name="left_ankle_roll" joint="left_ankle_roll_joint" ctrlrange="-19 19" />
    <motor name="left_ankle_pitch" joint="left_ankle_pitch_joint" ctrlrange="-66.88 66.88" />

    <motor name="right_hip_pitch" joint="right_hip_pitch_joint" ctrlrange="-360 360" />
    <motor name="right_hip_roll" joint="right_hip_roll_joint" ctrlrange="-360 360" />
    <motor name="right_hip_yaw" joint="right_hip_yaw_joint" ctrlrange="-360 360" />
    <motor name="right_knee" joint="right_knee_joint" ctrlrange="-360 360" />
    <motor name="right_ankle_roll" joint="right_ankle_roll_joint" ctrlrange="-19 19" />
    <motor name="right_ankle_pitch" joint="right_ankle_pitch_joint" ctrlrange="-66.88 66.88" />

    <motor name="waist_yaw" joint="waist_yaw_joint" ctrlrange="-120 120" />
    <motor name="waist_roll" joint="waist_roll_joint" ctrlrange="-180 180" />
    <motor name="waist_pitch" joint="waist_pitch_joint" ctrlrange="-180 180" />

    <motor name="left_shoulder_pitch" joint="left_shoulder_pitch_joint" ctrlrange="-130 130" />
    <motor name="left_shoulder_roll" joint="left_shoulder_roll_joint" ctrlrange="-60 60" />
    <motor name="left_shoulder_yaw" joint="left_shoulder_yaw_joint" ctrlrange="-60 60" />
    <motor name="left_elbow" joint="left_elbow_joint" ctrlrange="-60 60" />
    <motor name="left_wrist_roll" joint="left_wrist_roll_joint" ctrlrange="-60 60" />
    <motor name="left_wrist_pitch" joint="left_wrist_pitch_joint" ctrlrange="-10 10" />
    <motor name="left_wrist_yaw" joint="left_wrist_yaw_joint" ctrlrange="-10 10" />

    <motor name="right_shoulder_pitch" joint="right_shoulder_pitch_joint" ctrlrange="-130 130" />
    <motor name="right_shoulder_roll" joint="right_shoulder_roll_joint" ctrlrange="-60 60" />
    <motor name="right_shoulder_yaw" joint="right_shoulder_yaw_joint" ctrlrange="-60 60" />
    <motor name="right_elbow" joint="right_elbow_joint" ctrlrange="-60 60" />
    <motor name="right_wrist_roll" joint="right_wrist_roll_joint" ctrlrange="-60 60" />
    <motor name="right_wrist_pitch" joint="right_wrist_pitch_joint" ctrlrange="-10 10" />
    <motor name="right_wrist_yaw" joint="right_wrist_yaw_joint" ctrlrange="-10 10" />

    <motor name="head_pitch" joint="head_pitch_joint" ctrlrange="-50 50" />
    <motor name="head_yaw" joint="head_yaw_joint" ctrlrange="-50 50" />
  </actuator>

  <sensor>
    <jointpos name="left_hip_pitch_pos" joint="left_hip_pitch_joint" />
    <jointpos name="left_hip_roll_pos" joint="left_hip_roll_joint" />
    <jointpos name="left_hip_yaw_pos" joint="left_hip_yaw_joint" />
    <jointpos name="left_knee_pos" joint="left_knee_joint" />
    <jointpos name="left_ankle_roll_pos" joint="left_ankle_roll_joint" />
    <jointpos name="left_ankle_pitch_pos" joint="left_ankle_pitch_joint" />
    <jointpos name="right_hip_pitch_pos" joint="right_hip_pitch_joint" />
    <jointpos name="right_hip_roll_pos" joint="right_hip_roll_joint" />
    <jointpos name="right_hip_yaw_pos" joint="right_hip_yaw_joint" />
    <jointpos name="right_knee_pos" joint="right_knee_joint" />
    <jointpos name="right_ankle_roll_pos" joint="right_ankle_roll_joint" />
    <jointpos name="right_ankle_pitch_pos" joint="right_ankle_pitch_joint" />
    <jointpos name="waist_yaw_pos" joint="waist_yaw_joint" />
    <jointpos name="waist_roll_pos" joint="waist_roll_joint" />
    <jointpos name="waist_pitch_pos" joint="waist_pitch_joint" />
    <jointpos name="left_shoulder_pitch_pos" joint="left_shoulder_pitch_joint" />
    <jointpos name="left_shoulder_roll_pos" joint="left_shoulder_roll_joint" />
    <jointpos name="left_shoulder_yaw_pos" joint="left_shoulder_yaw_joint" />
    <jointpos name="left_elbow_pos" joint="left_elbow_joint" />
    <jointpos name="left_wrist_roll_pos" joint="left_wrist_roll_joint" />
    <jointpos name="left_wrist_pitch_pos" joint="left_wrist_pitch_joint" />
    <jointpos name="left_wrist_yaw_pos" joint="left_wrist_yaw_joint" />
    <jointpos name="right_shoulder_pitch_pos" joint="right_shoulder_pitch_joint" />
    <jointpos name="right_shoulder_roll_pos" joint="right_shoulder_roll_joint" />
    <jointpos name="right_shoulder_yaw_pos" joint="right_shoulder_yaw_joint" />
    <jointpos name="right_elbow_pos" joint="right_elbow_joint" />
    <jointpos name="right_wrist_roll_pos" joint="right_wrist_roll_joint" />
    <jointpos name="right_wrist_pitch_pos" joint="right_wrist_pitch_joint" />
    <jointpos name="right_wrist_yaw_pos" joint="right_wrist_yaw_joint" />
    <jointpos name="head_pitch_pos" joint="head_pitch_joint" />
    <jointpos name="head_yaw_pos" joint="head_yaw_joint" />

    <jointvel name="left_hip_pitch_vel" joint="left_hip_pitch_joint" />
    <jointvel name="left_hip_roll_vel" joint="left_hip_roll_joint" />
    <jointvel name="left_hip_yaw_vel" joint="left_hip_yaw_joint" />
    <jointvel name="left_knee_vel" joint="left_knee_joint" />
    <jointvel name="left_ankle_roll_vel" joint="left_ankle_roll_joint" />
    <jointvel name="left_ankle_pitch_vel" joint="left_ankle_pitch_joint" />
    <jointvel name="right_hip_pitch_vel" joint="right_hip_pitch_joint" />
    <jointvel name="right_hip_roll_vel" joint="right_hip_roll_joint" />
    <jointvel name="right_hip_yaw_vel" joint="right_hip_yaw_joint" />
    <jointvel name="right_knee_vel" joint="right_knee_joint" />
    <jointvel name="right_ankle_roll_vel" joint="right_ankle_roll_joint" />
    <jointvel name="right_ankle_pitch_vel" joint="right_ankle_pitch_joint" />
    <jointvel name="waist_yaw_vel" joint="waist_yaw_joint" />
    <jointvel name="waist_roll_vel" joint="waist_roll_joint" />
    <jointvel name="waist_pitch_vel" joint="waist_pitch_joint" />
    <jointvel name="left_shoulder_pitch_vel" joint="left_shoulder_pitch_joint" />
    <jointvel name="left_shoulder_roll_vel" joint="left_shoulder_roll_joint" />
    <jointvel name="left_shoulder_yaw_vel" joint="left_shoulder_yaw_joint" />
    <jointvel name="left_elbow_vel" joint="left_elbow_joint" />
    <jointvel name="left_wrist_roll_vel" joint="left_wrist_roll_joint" />
    <jointvel name="left_wrist_pitch_vel" joint="left_wrist_pitch_joint" />
    <jointvel name="left_wrist_yaw_vel" joint="left_wrist_yaw_joint" />
    <jointvel name="right_shoulder_pitch_vel" joint="right_shoulder_pitch_joint" />
    <jointvel name="right_shoulder_roll_vel" joint="right_shoulder_roll_joint" />
    <jointvel name="right_shoulder_yaw_vel" joint="right_shoulder_yaw_joint" />
    <jointvel name="right_elbow_vel" joint="right_elbow_joint" />
    <jointvel name="right_wrist_roll_vel" joint="right_wrist_roll_joint" />
    <jointvel name="right_wrist_pitch_vel" joint="right_wrist_pitch_joint" />
    <jointvel name="right_wrist_yaw_vel" joint="right_wrist_yaw_joint" />
    <jointvel name="head_pitch_vel" joint="head_pitch_joint" />
    <jointvel name="head_yaw_vel" joint="head_yaw_joint" />

    <jointactuatorfrc name="left_hip_pitch_torque" joint="left_hip_pitch_joint" />
    <jointactuatorfrc name="left_hip_roll_torque" joint="left_hip_roll_joint" />
    <jointactuatorfrc name="left_hip_yaw_torque" joint="left_hip_yaw_joint" />
    <jointactuatorfrc name="left_knee_torque" joint="left_knee_joint" />
    <jointactuatorfrc name="left_ankle_roll_torque" joint="left_ankle_roll_joint" />
    <jointactuatorfrc name="left_ankle_pitch_torque" joint="left_ankle_pitch_joint" />
    <jointactuatorfrc name="right_hip_pitch_torque" joint="right_hip_pitch_joint" />
    <jointactuatorfrc name="right_hip_roll_torque" joint="right_hip_roll_joint" />
    <jointactuatorfrc name="right_hip_yaw_torque" joint="right_hip_yaw_joint" />
    <jointactuatorfrc name="right_knee_torque" joint="right_knee_joint" />
    <jointactuatorfrc name="right_ankle_roll_torque" joint="right_ankle_roll_joint" />
    <jointactuatorfrc name="right_ankle_pitch_torque" joint="right_ankle_pitch_joint" />
    <jointactuatorfrc name="waist_yaw_torque" joint="waist_yaw_joint" />
    <jointactuatorfrc name="waist_roll_torque" joint="waist_roll_joint" />
    <jointactuatorfrc name="waist_pitch_torque" joint="waist_pitch_joint" />
    <jointactuatorfrc name="left_shoulder_pitch_torque" joint="left_shoulder_pitch_joint" />
    <jointactuatorfrc name="left_shoulder_roll_torque" joint="left_shoulder_roll_joint" />
    <jointactuatorfrc name="left_shoulder_yaw_torque" joint="left_shoulder_yaw_joint" />
    <jointactuatorfrc name="left_elbow_torque" joint="left_elbow_joint" />
    <jointactuatorfrc name="left_wrist_roll_torque" joint="left_wrist_roll_joint" />
    <jointactuatorfrc name="left_wrist_pitch_torque" joint="left_wrist_pitch_joint" />
    <jointactuatorfrc name="left_wrist_yaw_torque" joint="left_wrist_yaw_joint" />
    <jointactuatorfrc name="right_shoulder_pitch_torque" joint="right_shoulder_pitch_joint" />
    <jointactuatorfrc name="right_shoulder_roll_torque" joint="right_shoulder_roll_joint" />
    <jointactuatorfrc name="right_shoulder_yaw_torque" joint="right_shoulder_yaw_joint" />
    <jointactuatorfrc name="right_elbow_torque" joint="right_elbow_joint" />
    <jointactuatorfrc name="right_wrist_roll_torque" joint="right_wrist_roll_joint" />
    <jointactuatorfrc name="right_wrist_pitch_torque" joint="right_wrist_pitch_joint" />
    <jointactuatorfrc name="right_wrist_yaw_torque" joint="right_wrist_yaw_joint" />
    <jointactuatorfrc name="head_pitch_torque" joint="head_pitch_joint" />
    <jointactuatorfrc name="head_yaw_torque" joint="head_yaw_joint" />

    <framequat name="imu_quat" objtype="site" objname="imu" />
    <gyro name="imu_ang_vel" site="imu" />
    <accelerometer name="imu_acc" site="imu" />

    <framepos name="frame_pos" objtype="site" objname="imu" />
    <framelinvel name="imu_lin_vel" objtype="site" objname="imu" />

    <framequat name="secondary_imu_quat" objtype="site" objname="secondary_imu" />
    <gyro name="secondary_imu_gyro" site="secondary_imu" noise="5e-4" cutoff="34.9" />
    <accelerometer name="secondary_imu_acc" site="secondary_imu" noise="1e-2" cutoff="157" />
  </sensor>
</mujoco>
