<mujoco model="h2">
  <compiler angle="radian" meshdir="meshes/" autolimits="true" />
  <default>
    <default class="h2">
      <default class="visual">
        <geom type="mesh" contype="0" conaffinity="0" group="2" density="0" />
      </default>
      <default class="collision">
        <geom type="capsule" condim="1" group="3" priority="1" />
        <default class="foot_capsule">
          <geom size="0.01" />
        </default>
      </default>
    </default>
  </default>
  <asset>
    <mesh name="pelvis" content_type="model/stl" file="pelvis.stl" />
    <mesh name="left_hip_pitch_link" content_type="model/stl" file="left_hip_pitch_link.stl" />
    <mesh name="left_hip_roll_link" content_type="model/stl" file="left_hip_roll_link.stl" />
    <mesh name="left_hip_yaw_link" content_type="model/stl" file="left_hip_yaw_link.stl" />
    <mesh name="left_knee_link" content_type="model/stl" file="left_knee_link.stl" />
    <mesh name="left_ankle_roll_link" content_type="model/stl" file="left_ankle_roll_link.stl" />
    <mesh name="left_ankle_pitch_link" content_type="model/stl" file="left_ankle_pitch_link.stl" />
    <mesh name="right_hip_pitch_link" content_type="model/stl" file="right_hip_pitch_link.stl" />
    <mesh name="right_hip_roll_link" content_type="model/stl" file="right_hip_roll_link.stl" />
    <mesh name="right_hip_yaw_link" content_type="model/stl" file="right_hip_yaw_link.stl" />
    <mesh name="right_knee_link" content_type="model/stl" file="right_knee_link.stl" />
    <mesh name="right_ankle_roll_link" content_type="model/stl" file="right_ankle_roll_link.stl" />
    <mesh name="right_ankle_pitch_link" content_type="model/stl" file="right_ankle_pitch_link.stl" />
    <mesh name="waist_yaw_link" content_type="model/stl" file="waist_yaw_link.stl" />
    <mesh name="waist_roll_link" content_type="model/stl" file="waist_roll_link.stl" />
    <mesh name="torso_link" content_type="model/stl" file="torso_link.stl" />
    <mesh name="head_pitch_link" content_type="model/stl" file="head_pitch_link.stl" />
    <mesh name="head_yaw_link" content_type="model/stl" file="head_yaw_link.stl" />
    <mesh name="left_shoulder_pitch_link" content_type="model/stl" file="left_shoulder_pitch_link.stl" />
    <mesh name="left_shoulder_roll_link" content_type="model/stl" file="left_shoulder_roll_link.stl" />
    <mesh name="left_shoulder_yaw_link" content_type="model/stl" file="left_shoulder_yaw_link.stl" />
    <mesh name="left_elbow_link" content_type="model/stl" file="left_elbow_link.stl" />
    <mesh name="left_wrist_roll_link" content_type="model/stl" file="left_wrist_roll_link.stl" />
    <mesh name="left_wrist_pitch_link" content_type="model/stl" file="left_wrist_pitch_link.stl" />
    <mesh name="left_wrist_yaw_link" content_type="model/stl" file="left_wrist_yaw_link.stl" />
    <mesh name="right_shoulder_pitch_link" content_type="model/stl" file="right_shoulder_pitch_link.stl" />
    <mesh name="right_shoulder_roll_link" content_type="model/stl" file="right_shoulder_roll_link.stl" />
    <mesh name="right_shoulder_yaw_link" content_type="model/stl" file="right_shoulder_yaw_link.stl" />
    <mesh name="right_elbow_link" content_type="model/stl" file="right_elbow_link.stl" />
    <mesh name="right_wrist_roll_link" content_type="model/stl" file="right_wrist_roll_link.stl" />
    <mesh name="right_wrist_pitch_link" content_type="model/stl" file="right_wrist_pitch_link.stl" />
    <mesh name="right_wrist_yaw_link" content_type="model/stl" file="right_wrist_yaw_link.stl" />
  </asset>
  <worldbody>
    <body name="pelvis" pos="0 0 1.2" childclass="h2">
      <freejoint name="floating_base_joint" />
      <site name="imu" size="0.01" pos="0.0 0.0 0.0" />
      <geom type="mesh" rgba="0.7 0.7 0.7 1" mesh="pelvis" class="visual" />
      <geom name="pelvis_collision" class="collision" type="sphere" size="0.08" pos="0 0 0" />
      <body name="left_hip_pitch_link" pos="0 0.08038 -0.046407" quat="0.965926 -0.25882 0 0">
        <inertial pos="0.00294368 0.061102 -0.017351" quat="0.89044 0.453883 -0.0133707 -0.0304704" mass="2.8737" diaginertia="0.00537408 0.00421163 0.0036878" />
        <joint name="left_hip_pitch_joint" pos="0 0 0" axis="0 1 0" range="-2.4526 2.77542" />
        <geom type="mesh" rgba="0.4 0.4 0.4 1" mesh="left_hip_pitch_link" class="visual" />
        <body name="left_hip_roll_link" pos="0.041774 0.0635 -0.019" quat="0.965926 0.25882 0 0">
          <inertial pos="-0.0175789 -0.00607425 -0.041315" quat="-0.165515 0.598251 -0.0524355 0.782273" mass="0.785079" diaginertia="0.0023778 0.00200443 0.0015153" />
          <joint name="left_hip_roll_joint" pos="0 0 0" axis="1 0 0" range="-0.467441 2.16886" />
          <geom type="mesh" rgba="0.7 0.7 0.7 1" mesh="left_hip_roll_link" class="visual" />
          <geom name="left_hip_collision" class="collision" size="0.07" fromto="0.02 0 0 0.02 0 -0.10" />
          <body name="left_hip_yaw_link" pos="-0.028187 -0.0095 -0.0737">
            <inertial pos="0.00069408 -0.0108659 -0.113015" quat="0.621956 -0.0405938 0.0198649 0.781747" mass="7.0875" diaginertia="0.0514013 0.0505964 0.0130063" />
            <joint name="left_hip_yaw_joint" pos="0 0 0" axis="0 0 1" range="-2.827 2.827" />
            <geom type="mesh" rgba="0.7 0.7 0.7 1" mesh="left_hip_yaw_link" class="visual" />
            <geom name="left_thigh_collision" class="collision" size="0.065" fromto="0.0 0 -0.04 -0.07 0 -0.22" />
            <body name="left_knee_link" pos="-0.010308 0.022549 -0.31959">
              <inertial pos="0.00461331 -0.022549 -0.167155" quat="0.689662 0.00325283 0.00290593 0.724118" mass="4.3534" diaginertia="0.0512388 0.0510884 0.00333998" />
              <joint name="left_knee_joint" pos="0 0 0" axis="0 1 0" range="-0.08725 2.53025" />
              <geom type="mesh" rgba="0.7 0.7 0.7 1" mesh="left_knee_link" class="visual" />
              <geom name="left_shin_collision" class="collision" size="0.05" fromto="0.01 0 0 0.01 0 -0.20" />
              <geom name="left_linkage_brace_collision" class="collision" size="0.035" fromto="0.01 0 -0.25 0.01 0 -0.38" />
              <body name="left_ankle_roll_link" pos="0.032719 -0.023002 -0.49662">
                <inertial pos="-0.0174063 6.424e-05 -0.0002146" quat="0.499157 0.502573 -0.497809 0.500449" mass="0.123182" diaginertia="4.00501e-05 3.43207e-05 1.44993e-05" />
                <joint name="left_ankle_roll_joint" pos="0 0 0" axis="1 0 0" range="-0.349066 0.296706" />
                <geom type="mesh" rgba="0.7 0.7 0.7 1" mesh="left_ankle_roll_link" class="visual" />
                <body name="left_ankle_pitch_link" pos="-0.014516 -0.0373 0">
                  <inertial pos="0.032059 0.0370053 -0.0288282" quat="6.19452e-05 0.72345 -3.0004e-05 0.690377" mass="0.894967" diaginertia="0.00438317 0.00410964 0.000599978" />
                  <joint name="left_ankle_pitch_joint" pos="0 0 0" axis="0 1 0" range="-1.13446 0.610865" />
                  <geom type="mesh" rgba="0.4 0.4 0.4 1" mesh="left_ankle_pitch_link" class="visual" />
                  <geom size="0.008" pos="-0.075 0.066 -0.05" class="collision" name="left_ankle_pitch_link_sphere_collision" type="sphere" />
                  <geom size="0.008" pos="-0.075 0.007 -0.05" class="collision" name="left_ankle_pitch_link_sphere_collision_2" type="sphere" />
                  <geom size="0.008" pos="0.1 0.08 -0.048" class="collision" name="left_ankle_pitch_link_sphere_collision_3" type="sphere" />
                  <geom size="0.008" pos="0.1 -0.007 -0.048" class="collision" name="left_ankle_pitch_link_sphere_collision_4" type="sphere" />
                  <geom size="0.008" pos="0.15 0.066 -0.05" class="collision" name="left_ankle_pitch_link_sphere_collision_5" type="sphere" />
                  <geom size="0.008" pos="0.15 0.007 -0.05" class="collision" name="left_ankle_pitch_link_sphere_collision_6" type="sphere" />
                  <geom size="0.115 0.04 0.004" pos="0.035 0.0365 -0.04" type="box" class="collision" name="left_foot_sole_collision" />
                  <site name="left_foot" pos="0.035 0.0365 -0.04" size="0.01" />
                </body>
                <geom name="left_foot1_collision" class="foot_capsule" fromto="0.10 -0.026 -0.04 0.05 -0.027 -0.04" />
                <geom name="left_foot2_collision" class="foot_capsule" fromto="-0.04 -0.018 -0.04 0.12 -0.018 -0.04" />
                <geom name="left_foot3_collision" class="foot_capsule" fromto="-0.05 -0.010 -0.04 0.13 -0.010 -0.04" />
                <geom name="left_foot4_collision" class="foot_capsule" fromto="-0.05 0.000 -0.04 0.13 0.000 -0.04" />
                <geom name="left_foot5_collision" class="foot_capsule" fromto="-0.05 0.010 -0.04 0.13 0.010 -0.04" />
                <geom name="left_foot6_collision" class="foot_capsule" fromto="-0.04 0.018 -0.04 0.12 0.018 -0.04" />
                <geom name="left_foot7_collision" class="foot_capsule" fromto="0.10 0.026 -0.04 0.05 0.026 -0.04" />
              </body>
            </body>
          </body>
        </body>
      </body>
      <body name="right_hip_pitch_link" pos="0 -0.08038 -0.046407" quat="0.965926 0.25882 0 0">
        <inertial pos="0.00294368 -0.061102 -0.017351" quat="0.453883 0.89044 0.0304704 0.0133707" mass="2.8737" diaginertia="0.00537408 0.00421163 0.0036878" />
        <joint name="right_hip_pitch_joint" pos="0 0 0" axis="0 1 0" range="-2.4526 2.77542" />
        <geom type="mesh" rgba="0.4 0.4 0.4 1" mesh="right_hip_pitch_link" class="visual" />
        <body name="right_hip_roll_link" pos="0.041774 -0.0635 -0.019" quat="0.965926 -0.25882 0 0">
          <inertial pos="-0.0175789 0.00607425 -0.041315" quat="0.165515 0.598251 0.0524355 0.782273" mass="0.75122" diaginertia="0.0023778 0.00200443 0.0015153" />
          <joint name="right_hip_roll_joint" pos="0 0 0" axis="1 0 0" range="-2.16886 0.467441" />
          <geom type="mesh" rgba="0.7 0.7 0.7 1" mesh="right_hip_roll_link" class="visual" />
          <geom name="right_hip_collision" class="collision" size="0.07" fromto="0.02 0 0 0.02 0 -0.10" />
          <body name="right_hip_yaw_link" pos="-0.028187 0.0095 -0.0737">
            <inertial pos="0.00069408 0.0108659 -0.113015" quat="0.781747 0.0198649 -0.0405938 0.621956" mass="7.0875" diaginertia="0.0514013 0.0505964 0.0130063" />
            <joint name="right_hip_yaw_joint" pos="0 0 0" axis="0 0 1" range="-2.827 2.827" />
            <geom type="mesh" rgba="0.7 0.7 0.7 1" mesh="right_hip_yaw_link" class="visual" />
            <geom name="right_thigh_collision" class="collision" size="0.065" fromto="0.0 0 -0.04 -0.07 0 -0.22" />
            <body name="right_knee_link" pos="-0.010308 -0.022549 -0.31959">
              <inertial pos="0.00461331 0.022549 -0.167155" quat="0.724118 0.00290593 0.00325283 0.689662" mass="4.3534" diaginertia="0.0512388 0.0510884 0.00333998" />
              <joint name="right_knee_joint" pos="0 0 0" axis="0 1 0" range="-0.08725 2.53025" />
              <geom type="mesh" rgba="0.7 0.7 0.7 1" mesh="right_knee_link" class="visual" />
              <geom name="right_shin_collision" class="collision" size="0.05" fromto="0.01 0 0 0.01 0 -0.20" />
              <geom name="right_linkage_brace_collision" class="collision" size="0.035" fromto="0.01 0 -0.25 0.01 0 -0.38" />
              <body name="right_ankle_roll_link" pos="0.032719 0.023002 -0.49662">
                <inertial pos="-0.0174063 -6.424e-05 -0.0002146" quat="0.502573 0.499157 -0.500449 0.497809" mass="0.123182" diaginertia="4.00501e-05 3.43207e-05 1.44993e-05" />
                <joint name="right_ankle_roll_joint" pos="0 0 0" axis="1 0 0" range="-0.296706 0.349066" />
                <geom type="mesh" rgba="0.7 0.7 0.7 1" mesh="right_ankle_roll_link" class="visual" />
                <body name="right_ankle_pitch_link" pos="-0.014516 0.0373 0">
                  <inertial pos="0.032059 -0.0370053 -0.0288282" quat="-6.19452e-05 0.72345 3.0004e-05 0.690377" mass="0.894967" diaginertia="0.00438317 0.00410964 0.000599978" />
                  <joint name="right_ankle_pitch_joint" pos="0 0 0" axis="0 1 0" range="-1.13446 0.610865" />
                  <geom type="mesh" rgba="0.4 0.4 0.4 1" mesh="right_ankle_pitch_link" class="visual" />
                  <geom size="0.008" pos="-0.075 -0.066 -0.05" class="collision" name="right_ankle_pitch_link_sphere_collision" type="sphere" />
                  <geom size="0.008" pos="-0.075 -0.007 -0.05" class="collision" name="right_ankle_pitch_link_sphere_collision_2" type="sphere" />
                  <geom size="0.008" pos="0.1 -0.08 -0.048" class="collision" name="right_ankle_pitch_link_sphere_collision_3" type="sphere" />
                  <geom size="0.008" pos="0.1 0.007 -0.048" class="collision" name="right_ankle_pitch_link_sphere_collision_4" type="sphere" />
                  <geom size="0.008" pos="0.15 -0.066 -0.05" class="collision" name="right_ankle_pitch_link_sphere_collision_5" type="sphere" />
                  <geom size="0.008" pos="0.15 -0.007 -0.05" class="collision" name="right_ankle_pitch_link_sphere_collision_6" type="sphere" />
                  <geom size="0.115 0.04 0.004" pos="0.035 -0.0365 -0.04" type="box" class="collision" name="right_foot_sole_collision" />
                  <site name="right_foot" pos="0.035 -0.0365 -0.04" size="0.01" />
                </body>
                <geom name="right_foot1_collision" class="foot_capsule" fromto="0.10 0.026 -0.04 0.05 0.027 -0.04" />
                <geom name="right_foot2_collision" class="foot_capsule" fromto="-0.04 0.018 -0.04 0.12 0.018 -0.04" />
                <geom name="right_foot3_collision" class="foot_capsule" fromto="-0.05 0.01 -0.04 0.13 0.01 -0.04" />
                <geom name="right_foot4_collision" class="foot_capsule" fromto="-0.05 -0.0 -0.04 0.13 -0.0 -0.04" />
                <geom name="right_foot5_collision" class="foot_capsule" fromto="-0.05 -0.01 -0.04 0.13 -0.01 -0.04" />
                <geom name="right_foot6_collision" class="foot_capsule" fromto="-0.04 -0.018 -0.04 0.12 -0.018 -0.04" />
                <geom name="right_foot7_collision" class="foot_capsule" fromto="0.10 -0.026 -0.04 0.05 -0.026 -0.04" />
              </body>
            </body>
          </body>
        </body>
      </body>
      <body name="waist_yaw_link" pos="0 0 0.090537">
        <inertial pos="0.00648295 1.018e-05 0.0176063" quat="0.000115436 0.720073 0.000256241 0.693898" mass="0.312936" diaginertia="0.00033891 0.00028436 0.00012018" />
        <joint name="waist_yaw_joint" pos="0 0 0" axis="0 0 1" range="-1.7453 1.7453" />
        <geom type="mesh" rgba="0.7 0.7 0.7 1" mesh="waist_yaw_link" class="visual" />
        <body name="waist_roll_link" pos="0 0 0.0325">
          <inertial pos="0 0.00061119 0" quat="0.5 0.5 -0.5 0.5" mass="0.138419" diaginertia="2.304e-05 1.668e-05 1.509e-05" />
          <joint name="waist_roll_joint" pos="0 0 0" axis="1 0 0" range="-0.5236 0.5236" />
          <geom type="mesh" rgba="0.7 0.7 0.7 1" mesh="waist_roll_link" class="visual" />
          <body name="torso_link">
            <site name="secondary_imu" size="0.01" pos="0.0 0.0 0.0" />
            <inertial pos="0.00740421 0.00628045 0.215575" quat="0.99932 -0.0321662 -0.00775231 0.0162839" mass="18.532" diaginertia="0.287321 0.26278 0.0934525" />
            <joint name="waist_pitch_joint" pos="0 0 0" axis="0 1 0" range="-0.43633 0.5236" />
            <geom type="mesh" rgba="0.7 0.7 0.7 1" mesh="torso_link" class="visual" />
            <geom name="torso_collision" class="collision" size="0.11" fromto="0.01 0 0.10 0.01 0 0.28" />
            <body name="head_pitch_link" pos="-0.0001147 -0.0189 0.4218">
              <inertial pos="0.000126 0.018817 0.052939" quat="0.999996 -0.000955249 -0.00262397 -0.000580497" mass="1.82" diaginertia="0.00538697 0.00532442 0.00140982" />
              <joint name="head_pitch_joint" pos="0 0 0" axis="0 1 0" range="-0.5236 0.83775" />
              <geom type="mesh" rgba="0.7 0.7 0.7 1" mesh="head_pitch_link" class="visual" />
              <body name="head_yaw_link" pos="0 0.0189 0.1335">
                <inertial pos="0.023654 -0.000734 0.042315" quat="0.667311 -0.227767 -0.231751 0.670156" mass="1.3" diaginertia="0.00535274 0.00472336 0.00378091" />
                <joint name="head_yaw_joint" pos="0 0 0" axis="0 0 1" range="-1.7453 1.7453" />
                <geom type="mesh" rgba="0.7 0.7 0.7 1" mesh="head_yaw_link" class="visual" />
                <geom name="head_collision" class="collision" type="sphere" size="0.07" pos="0.02 0 0.05" />
              </body>
            </body>
            <body name="left_shoulder_pitch_link" pos="0.0030848 0.11 0.36008" quat="0.990959 0.134164 0 0">
              <inertial pos="-0.0027817 0.050393 -0.023914" quat="0.959427 0.279803 0.00644957 0.0341716" mass="1.1927" diaginertia="0.00174925 0.00162902 0.000852428" />
              <joint name="left_shoulder_pitch_joint" pos="0 0 0" axis="0 1 0" range="-2.618 1.833" />
              <geom type="mesh" rgba="0.7 0.7 0.7 1" mesh="left_shoulder_pitch_link" class="visual" />
              <body name="left_shoulder_roll_link" pos="-0.0032074 0.059938 -0.039865" quat="0.990959 -0.134164 0 0">
                <inertial pos="-0.00126759 0.00399799 -0.0665267" quat="0.719226 0.0130341 -0.00543937 0.694633" mass="1.10983" diaginertia="0.00193836 0.00176489 0.00106378" />
                <joint name="left_shoulder_roll_joint" pos="0 0 0" axis="1 0 0" range="-0.517 2.494" />
                <geom type="mesh" rgba="0.7 0.7 0.7 1" mesh="left_shoulder_roll_link" class="visual" />
                <body name="left_shoulder_yaw_link" pos="-0.0025601 0.0036752 -0.10421">
                  <inertial pos="0.00265957 0.0123454 -0.059622" quat="0.655577 0.0514587 -0.154929 0.737271" mass="0.352739" diaginertia="0.000897689 0.000854204 0.000287447" />
                  <joint name="left_shoulder_yaw_joint" pos="0 0 0" axis="0 0 1" range="-2.618 2.618" />
                  <geom type="mesh" rgba="0.7 0.7 0.7 1" mesh="left_shoulder_yaw_link" class="visual" />
                  <geom name="left_shoulder_yaw_collision" class="collision" size="0.04" fromto="0 0 -0.10 0 0 0.06" />
                  <body name="left_elbow_link" pos="0.016655 0.02211 -0.12792">
                    <inertial pos="0.0506767 -0.0216173 -0.00672238" quat="0.162352 0.731329 0.192833 0.633732" mass="1.70612" diaginertia="0.00522743 0.00521428 0.00111897" />
                    <joint name="left_elbow_joint" pos="0 0 0" axis="0 1 0" range="-0.986 3.071" />
                    <geom type="mesh" rgba="0.7 0.7 0.7 1" mesh="left_elbow_link" class="visual" />
                    <geom name="left_elbow_collision" class="collision" size="0.04" fromto="-0.01 0 -0.01 0.10 0 -0.01" />
                    <body name="left_wrist_roll_link" pos="0.13119 -0.021497 -0.013769">
                      <inertial pos="0.035915 -0.00154506 0.00012879" quat="0.349429 0.616315 -0.3656 0.603649" mass="0.77426" diaginertia="0.000715547 0.000661189 0.000632495" />
                      <joint name="left_wrist_roll_joint" pos="0 0 0" axis="1 0 0" range="-2.618 2.618" />
                      <geom type="mesh" rgba="0.7 0.7 0.7 1" mesh="left_wrist_roll_link" class="visual" />
                      <body name="left_wrist_pitch_link" pos="0.037994 0.031144 0.00045104">
                        <inertial pos="0.0651093 -0.0317607 0.00235463" quat="0.491682 0.228754 0.718653 0.435268" mass="0.615258" diaginertia="0.000423535 0.000417983 0.000396162" />
                        <joint name="left_wrist_pitch_joint" pos="0 0 0" axis="0 1 0" range="-0.576 0.576" />
                        <geom type="mesh" rgba="0.7 0.7 0.7 1" mesh="left_wrist_pitch_link" class="visual" />
                        <geom name="left_wrist_collision" class="collision" size="0.04" fromto="-0.01 0 0 0.08 0 0" />
                        <body name="left_wrist_yaw_link" pos="0.069283 -0.031045 -0.0006247">
                          <inertial pos="0.0800267 -0.00476807 0.00340465" quat="0.488112 0.56744 0.412641 0.51912" mass="0.616082" diaginertia="0.00189912 0.00166583 0.000524241" />
                          <joint name="left_wrist_yaw_joint" pos="0 0 0" axis="0 0 1" range="-1.22 1.22" />
                          <geom type="mesh" rgba="0.4 0.4 0.4 1" mesh="left_wrist_yaw_link" class="visual" />
                          <geom name="left_hand_collision" class="collision" size="0.04" fromto="0.09 0 0 0.18 -0.02 0" />
                        </body>
                      </body>
                    </body>
                  </body>
                </body>
              </body>
            </body>
            <body name="right_shoulder_pitch_link" pos="0.0030848 -0.11 0.36008" quat="0.990959 -0.134164 0 0">
              <inertial pos="-0.0027814 -0.050393 -0.023914" quat="0.959425 -0.279804 0.00643587 -0.0342398" mass="1.1927" diaginertia="0.00174925 0.00162902 0.000852428" />
              <joint name="right_shoulder_pitch_joint" pos="0 0 0" axis="0 1 0" range="-2.618 1.833" />
              <geom type="mesh" rgba="0.7 0.7 0.7 1" mesh="right_shoulder_pitch_link" class="visual" />
              <body name="right_shoulder_roll_link" pos="-0.0032074 -0.059938 -0.039865" quat="0.990959 0.134164 0 0">
                <inertial pos="-0.00126782 -0.0039981 -0.0665261" quat="0.694607 -0.0054503 0.0130148 0.719251" mass="1.10982" diaginertia="0.00193838 0.00176496 0.00106379" />
                <joint name="right_shoulder_roll_joint" pos="0 0 0" axis="1 0 0" range="-2.494 0.517" />
                <geom type="mesh" rgba="0.7 0.7 0.7 1" mesh="right_shoulder_roll_link" class="visual" />
                <body name="right_shoulder_yaw_link" pos="-0.0025601 -0.0036752 -0.10421">
                  <inertial pos="0.00266059 -0.0123451 -0.0596234" quat="0.737262 -0.154921 0.0514524 0.65559" mass="0.352742" diaginertia="0.000897692 0.000854184 0.000287444" />
                  <joint name="right_shoulder_yaw_joint" pos="0 0 0" axis="0 0 1" range="-2.618 2.618" />
                  <geom type="mesh" rgba="0.7 0.7 0.7 1" mesh="right_shoulder_yaw_link" class="visual" />
                  <geom name="right_shoulder_yaw_collision" class="collision" size="0.04" fromto="0 0 -0.10 0 0 0.06" />
                  <body name="right_elbow_link" pos="0.016655 -0.02211 -0.12792">
                    <inertial pos="0.0506784 0.0216171 -0.00672338" quat="-0.1624 0.731318 -0.192894 0.633713" mass="1.70617" diaginertia="0.00522767 0.0052145 0.00111905" />
                    <joint name="right_elbow_joint" pos="0 0 0" axis="0 1 0" range="-0.986 3.071" />
                    <geom type="mesh" rgba="0.7 0.7 0.7 1" mesh="right_elbow_link" class="visual" />
                    <geom name="right_elbow_collision" class="collision" size="0.04" fromto="-0.01 0 -0.01 0.10 0 -0.01" />
                    <body name="right_wrist_roll_link" pos="0.13119 0.021497 -0.013769">
                      <inertial pos="0.0359137 0.00155865 0.00014187" quat="0.61587 0.348982 -0.602387 0.368844" mass="0.774265" diaginertia="0.00071595 0.000661595 0.000632525" />
                      <joint name="right_wrist_roll_joint" pos="0 0 0" axis="1 0 0" range="-2.618 2.618" />
                      <geom type="mesh" rgba="0.7 0.7 0.7 1" mesh="right_wrist_roll_link" class="visual" />
                      <body name="right_wrist_pitch_link" pos="0.037994 -0.031144 0.00045104">
                        <inertial pos="0.0651131 0.0317523 0.00231986" quat="0.440426 0.716762 0.242507 0.483185" mass="0.615837" diaginertia="0.000424256 0.000418373 0.000396861" />
                        <joint name="right_wrist_pitch_joint" pos="0 0 0" axis="0 1 0" range="-0.576 0.576" />
                        <geom type="mesh" rgba="0.7 0.7 0.7 1" mesh="right_wrist_pitch_link" class="visual" />
                        <geom name="right_wrist_collision" class="collision" size="0.04" fromto="-0.01 0 0 0.08 0 0" />
                        <body name="right_wrist_yaw_link" pos="0.069283 0.031045 -0.0006247">
                          <inertial pos="0.0800267 0.00476817 0.00340501" quat="0.519117 0.41264 0.567453 0.488102" mass="0.616082" diaginertia="0.00189915 0.00166585 0.00052423" />
                          <joint name="right_wrist_yaw_joint" pos="0 0 0" axis="0 0 1" range="-1.22 1.22" />
                          <geom type="mesh" rgba="0.4 0.4 0.4 1" mesh="right_wrist_yaw_link" class="visual" />
                          <geom name="right_hand_collision" class="collision" size="0.04" fromto="0.09 0 0 0.18 0.02 0" />
                        </body>
                      </body>
                    </body>
                  </body>
                </body>
              </body>
            </body>
          </body>
        </body>
      </body>
    </body>
  </worldbody>
  <contact>
    <exclude body1="left_elbow_link" body2="left_wrist_pitch_link" />
    <exclude body1="right_elbow_link" body2="right_wrist_pitch_link" />
    <exclude body1="pelvis" body2="left_hip_roll_link" />
    <exclude body1="pelvis" body2="right_hip_roll_link" />
  </contact>
  <sensor>
    <gyro name="imu_ang_vel" site="imu" />
    <velocimeter name="imu_lin_vel" site="imu" />
    <accelerometer name="imu_lin_acc" site="imu" />
    <subtreeangmom name="root_angmom" body="pelvis" />
  </sensor>
</mujoco>
